Workbook

Sheet Topes_2026
A1: OFICINA ASUNTOS DOCENTES | B1: Columna1 | C1: Columna2 | D1: Columna3 | E1: Columna4 | F1: Columna5 | G1: Columna6 | H1: Columna7 | I1: Columna8 | J1: Columna9 | K1: Columna10 | L1: Columna11 | M1: Columna12 | N1: Columna13 | O1: Columna14 | P1: Columna15 | Q1: Columna16 | R1: Columna17 | S1: Columna18 | T1: Columna19 | U1: Columna20 | V1: Columna21 | W1: Columna22 | X1: Columna23 | Y1: Columna24 | Z1: Columna25 | AA1: Columna26 | AB1: Columna27 | AC1: Columna28 | AD1: Columna29 | AE1: Columna30 | AF1: Columna31 | AG1: Columna32 | AH1: Columna33 | AI1: Columna34 | AJ1: Columna35 | AK1: Columna36 | AL1: Columna37 | AM1: Columna38 | AN1: Columna39 | AO1: Columna40
A2: INFORME DE TOPES DE PUNTOS ASIGNADOS POR CATEGORÍAS
A3: 2009 - 2026
A4: No. | B4: APELLIDOS Y NOMBRE | C4: CÉDULA DE CIUDADANÍA O EXTRANJERÍA | D4: DEPENDENCIA DIRECTA | E4: FACULTAD | F4: ESCOLARIDAD | G4: DEDICACIÓN | H4: FECHA DE INGRESO | I4: CATEGORÍA | J4: TOTAL PUNTOS A DICIEMBRE DE 2009 | K4: TOTAL PUNTOS A DICIEMBRE DE 2010 | L4: TOTAL PUNTOS A DICIEMBRE DE 2011 | M4: PUNTOS PRODUCT.ACADEM. 2012 | N4: PUNTOS PRODUCT.ACADEM. 2013 | O4: PUNTOS PRODUCT.ACADEM. 2014 | P4: PUNTOS PRODUCT.ACADEM. 2015 | Q4: PUNTOS PRODUCT.ACADEM. 2016 | R4: PUNTOS PRODUCT.ACADEM. DIC_2017 | S4: PUNTOS PRODUCT.ACADEM. DIC_2018 | T4: PUNTOS PRODUCT.ACADEM. DIC_2019 | U4: PUNTOS PRODUCT.ACADEM. DIC_2020 | V4: PUNTOS PRODUCT.ACADEM. DIC_2021 | W4: PUNTOS PRODUCT.ACADEM. DIC_2022 | X4: PUNTOS PRODUCT.ACADEM. ENE-DIC_2023 | Y4: PUNTOS PRODUCT.ACADEM. ENE-DIC_2024 | Z4: PUNTOS PRODUCT.ACADEM. ENE-DIC_2025 | AA4: TOPE | AB4: DIFERENCIA ENTRE EL TOPE Y EL PUNTAJE ASIGNADO | AC4: CIARP- 01 2026 18 Mar | AK4: PUNTOS A FAVOR | AL4: TOPE POR LIBROS (Max. 35 Puntos) | AM4: TOPE POR SOFTWARE (Max. 35 Puntos) | AN4: COMISION ACADÉMICO ADMINISTRATIVA | AO4: OBSERVACIÓN
A5: 1 | B5: BERMUDEZ RESTREPO CAROLINA | C5: 24606935 | D5: Administración de Negocios | E5: Ciencias Económicas | F5: Maestría | G5: TC | H5: 43864 | I5: Auxiliar | U5: 0 | V5: 0 | W5: 1.5 | X5: 3 | Y5: 0 | Z5: 0 | AA5: 80 | AB5: =AA5-(J5+K5+L5+M5+N5+O5+P5+Q5+R5+S5+T5+U5+V5+W5+X5+Y5+Z5) -> 75.5 | AK5: =AB5-AC5-AD5-AE5-AF5-AG5-AH5-AI5-AJ5 -> 75.5
A6: 2 | B6: GARCÍA GIRALDO CARLOS ANDRÉS | C6: 89007946 | D6: Administración de Negocios | E6: Ciencias Económicas | F6: Maestría | G6: TC | H6: 44963 | I6: Asistente | X6: 0 | Y6: 35 | Z6: 37.9 | AA6: 160 | AB6: =AA6-(J6+K6+L6+M6+N6+O6+P6+Q6+R6+S6+T6+U6+V6+W6+X6+Y6+Z6) -> 87.1 | AC6: =Pub_Rev_Index!X10+Pub_Rev_Index!X12 -> 11 | AK6: =AB6-AC6-AD6-AE6-AF6-AG6-AH6-AI6-AJ6 -> 76.1
A7: 3 | B7: GIRALDO CORREA MARÍA PATRICIA | C7: 24809412 | D7: Administración de Negocios | E7: Ciencias Económicas | F7: Doctorado | G7: TC | H7: Ago.08/2017 | I7: Asociado | S7: 12.2 | T7: 26.6 | U7: 8 | V7: 13.1 | W7: 1.5 | X7: 3 | Y7: 27.9 | Z7: 10 | AA7: 320 | AB7: =AA7-(J7+K7+L7+M7+N7+O7+P7+Q7+R7+S7+T7+U7+V7+W7+X7+Y7+Z7) -> 217.7 | AK7: =AB7-AC7-AD7-AE7-AF7-AG7-AH7-AI7-AJ7 -> 217.7 | AO7: Inició comisión académico-admon el 01/06/2023 como Directora del Programa de Administración de Negocios -Terminó Comisión el 19 de junio de 2025
A8: 4 | B8: GUZMAN DIAZ BEATRIZ ELENA | C8: 41935384 | D8: Administración de Negocios | E8: Ciencias Económicas | F8: Maestría | G8: TC | H8: 41436 | I8: Titular | O8: 10 | R8: 27 | S8: 8 | T8: 39 | U8: 8 | V8: 45.3 | W8: 24.5 | X8: 19.9 | Y8: 8 | Z8: 31 | AA8: 540 | AB8: =AA8-(J8+K8+L8+M8+N8+O8+P8+Q8+R8+S8+T8+U8+V8+W8+X8+Y8+Z8) -> 319.3 | AK8: =AB8-AC8-AD8-AE8-AF8-AG8-AH8-AI8-AJ8 -> 319.3
A9: 5 | B9: JARAMILLO LOTERO RAFAEL ALEXANDER | C9: 7558182 | D9: Administración de Negocios | E9: Ciencias Económicas | F9: Maestría | G9: TC | H9: 43864 | I9: Asistente | U9: 3 | V9: 0 | W9: 0 | X9: 0 | Y9: 30.9 | Z9: 9.9 | AA9: 160 | AB9: =AA9-(J9+K9+L9+M9+N9+O9+P9+Q9+R9+S9+T9+U9+V9+W9+X9+Y9+Z9) -> 116.2 | AK9: =AB9-AC9-AD9-AE9-AF9-AG9-AH9-AI9-AJ9 -> 116.2
A10: 6 | B10: PARRA HERNÁNDEZ RAMIRO | C10: 7557752 | D10: Administración de Negocios | E10: Ciencias Económicas | F10: Maestría | G10: TC | H10: 04/082008 | I10: Asociado | J10: 14.2 | K10: 12.5 | M10: 14.6 | N10: 3 | Q10: 3 | R10: 27 | S10: 8 | T10: 39 | U10: 8 | V10: 30.3 | W10: 0 | X10: 12.4 | Y10: 8 | Z10: 29 | AA10: 320 | AB10: =AA10-(J10+K10+L10+M10+N10+O10+P10+Q10+R10+S10+T10+U10+V10+W10+X10+Y10+Z10) -> 111 | AK10: =AB10-AC10-AD10-AE10-AF10-AG10-AH10-AI10-AJ10 -> 111
A11: 7 | B11: TORRES QUINTERO LAURA LICETH | C11: 1094947500 | D11: Administración de Negocios | E11: Ciencias Económicas | F11: Doctorado | G11: TC | H11: 44963 | I11: Auxiliar | X11: 0 | Y11: 0 | Z11: 0 | AA11: 80 | AB11: =AA11-(J11+K11+L11+M11+N11+O11+P11+Q11+R11+S11+T11+U11+V11+W11+X11+Y11+Z11) -> 80 | AK11: =AB11-AC11-AD11-AE11-AF11-AG11-AH11-AI11-AJ11 -> 80
A12: 8 | B12: ARRUBLA FRANCO MARIBETH | C12: 29332068 | D12: Administración Financiera | E12: Ciencias Económicas | F12: Doctorado | G12: TC | H12: 40203 | I12: Titular | L12: 30.1 | M12: 18.9 | R12: 6 | U12: 0 | V12: 13.5 | W12: 12.2 | X12: 36.4 | Y12: 11.3 | Z12: 12.4 | AA12: 540 | AB12: =AA12-(J12+K12+L12+M12+N12+O12+P12+Q12+R12+S12+T12+U12+V12+W12+X12+Y12+Z12) -> 399.2 | AK12: =AB12-AC12-AD12-AE12-AF12-AG12-AH12-AI12-AJ12 -> 399.2 | AN12: 12,4 puntos CIARP 7 29/10/2025 | AO12: Inició comisión académico-admon el 07/05/2025 como Directora del Programa de Administración Financiera
A13: 9 | B13: CAICEDO GONZÁLEZ IVONNE | C13: 29226257 | D13: Administración Financiera | E13: Ciencias Económicas | F13: Maestría | G13: TC | H13: 44963 | I13: Asociado | X13: 29.2 | Y13: 0 | Z13: 50 | AA13: 320 | AB13: =AA13-(J13+K13+L13+M13+N13+O13+P13+Q13+R13+S13+T13+U13+V13+W13+X13+Y13+Z13) -> 240.8 | AK13: =AB13-AC13-AD13-AE13-AF13-AG13-AH13-AI13-AJ13 -> 240.8
A14: 10 | B14: HOYOS WALTEROS HERNÁN | C14: 7554040 | D14: Administración Financiera | E14: Ciencias Económicas | F14: Maestría | G14: TC | H14: 39664 | I14: Titular | J14: 69.8 | Q14: 6.4 | R14: 29.2 | S14: 33.4 | T14: 35 | U14: 0 | V14: 40.5 | W14: 0 | X14: 0 | Y14: 12.3 | Z14: 43.7 | AA14: 540 | AB14: =AA14-(J14+K14+L14+M14+N14+O14+P14+Q14+R14+S14+T14+U14+V14+W14+X14+Y14+Z14) -> 269.7 | AK14: =AB14-AC14-AD14-AE14-AF14-AG14-AH14-AI14-AJ14 -> 269.7
A15: 11 | B15: ROMAN VALENCIA BERLY | C15: 41916725 | D15: Administración Financiera | E15: Ciencias Económicas | F15: Maestría | G15: TC | H15: 44963 | I15: Auxiliar | X15: 0 | Y15: 11.7 | Z15: 38 | AA15: 80 | AB15: =AA15-(J15+K15+L15+M15+N15+O15+P15+Q15+R15+S15+T15+U15+V15+W15+X15+Y15+Z15) -> 30.3 | AC15: =Pub_Rev_Index!X13 -> 8 | AK15: =AB15-AC15-AD15-AE15-AF15-AG15-AH15-AI15-AJ15 -> 22.3
A16: 12 | B16: CASTAÑEDA PATIÑO JUAN CARLOS | C16: 7551802 | D16: Artes Visuales | E16: Ciencias Humanas | F16: Doctorado | G16: TC | H16: 43951 | I16: Asistente | U16: 10.1 | V16: 15.9 | W16: 0 | X16: 0 | Y16: 0 | Z16: 0 | AA16: 160 | AB16: =AA16-(J16+K16+L16+M16+N16+O16+P16+Q16+R16+S16+T16+U16+V16+W16+X16+Y16+Z16) -> 134 | AK16: =AB16-AC16-AD16-AE16-AF16-AG16-AH16-AI16-AJ16 -> 134
A17: 13 | B17: GUTIÉRREZ MORENO MILDRED EUGENIA | C17: 41914131 | D17: Artes Visuales | E17: Ciencias Humanas | F17: Maestría | G17: TC | H17: 41872 | I17: Auxiliar | U17: 0 | V17: 0 | W17: 0 | X17: 0 | Y17: 0 | Z17: 0 | AA17: 80 | AB17: =AA17-(J17+K17+L17+M17+N17+O17+P17+Q17+R17+S17+T17+U17+V17+W17+X17+Y17+Z17) -> 80 | AK17: =AB17-AC17-AD17-AE17-AF17-AG17-AH17-AI17-AJ17 -> 80
A18: 14 | B18: MARTÍNEZ PLAZAS MARIO ANDRÉS | C18: 9727322 | D18: Artes Visuales | E18: Ciencias Humanas | F18: Maestría | G18: TC | H18: 44963 | I18: Auxiliar | X18: 3 | Y18: 0 | Z18: 0 | AA18: 80 | AB18: =AA18-(J18+K18+L18+M18+N18+O18+P18+Q18+R18+S18+T18+U18+V18+W18+X18+Y18+Z18) -> 77 | AK18: =AB18-AC18-AD18-AE18-AF18-AG18-AH18-AI18-AJ18 -> 77
A19: 15 | B19: AGUILLÓN OSMA JOHANNY | C19: 94287028 | D19: Biología | E19: Ciencias Básicas | F19: Doctorado | G19: TC | H19: 44966 | I19: Asistente | X19: 63.7 | Y19: 4 | Z19: 10 | AA19: 160 | AB19: =AA19-(J19+K19+L19+M19+N19+O19+P19+Q19+R19+S19+T19+U19+V19+W19+X19+Y19+Z19) -> 82.3 | AK19: =AB19-AC19-AD19-AE19-AF19-AG19-AH19-AI19-AJ19 -> 82.3
A20: 16 | B20: AGUIRRE OBANDO OSCAR ALEXANDER | C20: 9732828 | D20: Biología | E20: Ciencias Básicas | F20: Doctorado | G20: TC | H20: 43878 | I20: Asociado | U20: 45 | V20: 42.5 | W20: 7.5 | X20: 32 | Y20: 4 | Z20: 51 | AA20: 320 | AB20: =AA20-(J20+K20+L20+M20+N20+O20+P20+Q20+R20+S20+T20+U20+V20+W20+X20+Y20+Z20) -> 138 | AK20: =AB20-AC20-AD20-AE20-AF20-AG20-AH20-AI20-AJ20 -> 138
A21: 17 | B21: GARCIA CARDENAS DELLY ROCIO | C21: 66920157 | D21: Biología | E21: Ciencias Básicas | F21: Doctorado | G21: TC | H21: 39664 | I21: Asociado | J21: 15 | K21: 12 | M21: 21 | O21: 1.8 | R21: 12 | T21: 12 | U21: 0 | V21: 0 | W21: 0 | X21: 7.5 | Y21: 0 | Z21: 5 | AA21: 320 | AB21: =AA21-(J21+K21+L21+M21+N21+O21+P21+Q21+R21+S21+T21+U21+V21+W21+X21+Y21+Z21) -> 233.7 | AK21: =AB21-AC21-AD21-AE21-AF21-AG21-AH21-AI21-AJ21 -> 233.7
A22: 18 | B22: GARCÍA MERCHAN VICTOR HUGO | C22: 89006379 | D22: Biología | E22: Ciencias Básicas | F22: Doctorado | G22: TC | H22: 38140 | I22: Titular | J22: 2.9 | M22: 4 | O22: 33 | P22: 14.4 | Q22: 15 | R22: 18.8 | T22: 6.4 | U22: 41.3 | V22: 12.5 | W22: 3 | X22: 3.8 | Y22: 12 | Z22: 9 | AA22: 540 | AB22: =AA22-(J22+K22+L22+M22+N22+O22+P22+Q22+R22+S22+T22+U22+V22+W22+X22+Y22+Z22) -> 363.9 | AK22: =AB22-AC22-AD22-AE22-AF22-AG22-AH22-AI22-AJ22 -> 363.9
A23: 19 | B23: GIRALDO GARCÍA ALEJANDRA MARÍA | C23: 24675452 | D23: Biología | E23: Ciencias Básicas | F23: Maestría | G23: TC | H23: 42955 | I23: Asistente | R23: 56.7 | U23: 35.8 | V23: 0 | W23: 0 | X23: 0.6 | Y23: 0 | Z23: 0 | AA23: 160 | AB23: =AA23-(J23+K23+L23+M23+N23+O23+P23+Q23+R23+S23+T23+U23+V23+W23+X23+Y23+Z23) -> 66.9 | AK23: =AB23-AC23-AD23-AE23-AF23-AG23-AH23-AI23-AJ23 -> 66.9 | AN23: 0,6 puntos CIARP 5-05/06/23 | AO23: Inició comisión académico-admon el 03/05/2023 como Vicerrectora de Extensión
A24: 20 | B24: GÓMEZ MARÍN GERMÁN DARÍO | C24: 89006235 | D24: Biología | E24: Ciencias Básicas | F24: Maestría | G24: TC | H24: 45028 | I24: Asistente | X24: 17.8 | Y24: 0 | Z24: 18.7 | AA24: 160 | AB24: =AA24-(J24+K24+L24+M24+N24+O24+P24+Q24+R24+S24+T24+U24+V24+W24+X24+Y24+Z24) -> 123.5 | AK24: =AB24-AC24-AD24-AE24-AF24-AG24-AH24-AI24-AJ24 -> 123.5
A25: 21 | B25: LOANGO CHAMORRO NELSY | C25: 66736378 | D25: Biología | E25: Ciencias Básicas | F25: Doctorado | G25: TC | H25: 39153 | I25: Titular | J25: 37.2 | K25: 15 | L25: 17.3 | M25: 27 | N25: 34.5 | O25: 7.5 | P25: 6 | Q25: 6 | S25: 9.5 | T25: 6 | U25: 19.2 | V25: 0 | W25: 8 | X25: 5.5 | Y25: 4 | Z25: 10.4 | AA25: 540 | AB25: =AA25-(J25+K25+L25+M25+N25+O25+P25+Q25+R25+S25+T25+U25+V25+W25+X25+Y25+Z25) -> 326.9 | AK25: =AB25-AC25-AD25-AE25-AF25-AG25-AH25-AI25-AJ25 -> 326.9
A26: 22 | B26: LORA SUÁREZ FABIANA MARÍA | C26: 41935619 | D26: Biología | E26: Ciencias Básicas | F26: Doctorado | G26: TC | H26: 42955 | I26: Asistente | R26: 65.5 | S26: 15 | U26: 42.2 | V26: 22.5 | W26: 4 | X26: 5.5 | Y26: 5.3 | Z26: 0 | AA26: 160 | AB26: =AA26-(J26+K26+L26+M26+N26+O26+P26+Q26+R26+S26+T26+U26+V26+W26+X26+Y26+Z26) -> 0 | AK26: =AB26-AC26-AD26-AE26-AF26-AG26-AH26-AI26-AJ26 -> 0
A27: 23 | B27: MANTILLA MELUK HUGO | C27: 79400867 | D27: Biología | E27: Ciencias Básicas | F27: Doctorado | G27: TC | H27: 41492 | I27: Asistente | N27: 80 | O27: 30 | P27: 50 | U27: 0 | V27: 0 | W27: 0 | X27: 0 | Y27: 0 | Z27: 0 | AA27: 160 | AB27: =AA27-(J27+K27+L27+M27+N27+O27+P27+Q27+R27+S27+T27+U27+V27+W27+X27+Y27+Z27) -> 0 | AK27: =AB27-AC27-AD27-AE27-AF27-AG27-AH27-AI27-AJ27 -> 0
A28: 24 | B28: ROMAN VALENCIA CESAR | C28: 7535130 | D28: Biología | E28: Ciencias Básicas | F28: Doctorado | G28: TC | H28: 34178 | I28: Titular | J28: 303.5 | K28: 70.5 | L28: 81 | M28: 36 | N28: 22.5 | O28: 28.5 | U28: 0 | V28: 0 | W28: 0 | X28: 0 | Y28: 0 | Z28: 0 | AA28: 540 | AB28: =AA28-(J28+K28+L28+M28+N28+O28+P28+Q28+R28+S28+T28+U28+V28+W28+X28+Y28+Z28) -> -2 | AK28: =AB28-AC28-AD28-AE28-AF28-AG28-AH28-AI28-AJ28 -> -2
A29: 25 | B29: SEPÚLVEDA NIETO MARÍA DEL PILAR | C29: 41922237 | D29: Biología | E29: Ciencias Básicas | F29: Maestría | G29: TC | H29: 40203 | I29: Asistente | K29: 1.9 | O29: 3 | T29: 15.5 | U29: 6 | V29: 0 | W29: 0 | X29: 0 | Y29: 0 | Z29: 12 | AA29: 160 | AB29: =AA29-(J29+K29+L29+M29+N29+O29+P29+Q29+R29+S29+T29+U29+V29+W29+X29+Y29+Z29) -> 121.6 | AK29: =AB29-AC29-AD29-AE29-AF29-AG29-AH29-AI29-AJ29 -> 121.6
A30: 26 | B30: VALENCIA ROJAS MÓNICA PATRICIA | C30: 25283616 | D30: Biología | E30: Ciencias Básicas | F30: Doctorado | G30: TC | H30: 43864 | I30: Asociado | U30: 51 | V30: 0 | W30: 0 | X30: 0 | Y30: 0 | Z30: 0 | AA30: 320 | AB30: =AA30-(J30+K30+L30+M30+N30+O30+P30+Q30+R30+S30+T30+U30+V30+W30+X30+Y30+Z30) -> 269 | AK30: =AB30-AC30-AD30-AE30-AF30-AG30-AH30-AI30-AJ30 -> 269
A31: 27 | B31: VARGAS SALINAS FERNANDO | C31: 94378416 | D31: Biología | E31: Ciencias Básicas | F31: Doctorado | G31: TC | H31: 41436 | I31: Titular | N31: 74.7 | O31: 45.8 | P31: 36.3 | Q31: 30 | S31: 58.7 | T31: 34 | U31: 13.1 | V31: 27.4 | W31: 49.9 | X31: 20.2 | Y31: 56.6 | Z31: 55.2 | AA31: 540 | AB31: =AA31-(J31+K31+L31+M31+N31+O31+P31+Q31+R31+S31+T31+U31+V31+W31+X31+Y31+Z31) -> 38.1 | AK31: =AB31-AC31-AD31-AE31-AF31-AG31-AH31-AI31-AJ31 -> 38.1
A32: 28 | B32: CASTRO BENAVIDES LINA MARÍA | C32: 41942253 | D32: Ciencia de la Información y la Documentación, Bibliotecología y Archivística | E32: Ciencias Humanas | F32: Doctorado | G32: TC | H32: 41883 | I32: Asociado | O32: 12.7 | Q32: 57.8 | R32: 14.4 | S32: 11.5 | T32: 4 | U32: 0 | V32: 11.8 | W32: 0 | X32: 15.5 | Y32: 0 | Z32: 0 | AA32: 320 | AB32: =AA32-(J32+K32+L32+M32+N32+O32+P32+Q32+R32+S32+T32+U32+V32+W32+X32+Y32+Z32) -> 192.3 | AK32: =AB32-AC32-AD32-AE32-AF32-AG32-AH32-AI32-AJ32 -> 192.3
A33: 29 | B33: HERNÁNDEZ CARVAJAL ANDRÉS MAURICIO | C33: 1094878677 | D33: Ciencia de la Información y la Documentación, Bibliotecología y Archivística | E33: Ciencias Humanas | F33: Maestría | G33: TC | H33: 45091 | I33: Asistente | X33: 43.3 | Y33: 36.3 | Z33: 80.4 | AA33: 160 | AB33: =AA33-(J33+K33+L33+M33+N33+O33+P33+Q33+R33+S33+T33+U33+V33+W33+X33+Y33+Z33) -> 0 | AK33: =AB33-AC33-AD33-AE33-AF33-AG33-AH33-AI33-AJ33 -> 0
A34: 30 | B34: RAMÍREZ AGUDELO ANGÉLICA MARÍA | C34: 41955076 | D34: Ciencia de la Información y la Documentación, Bibliotecología y Archivística | E34: Ciencias Humanas | F34: Maestría | G34: TC | H34: 45078 | I34: Auxiliar | X34: 0 | Y34: 0 | Z34: 0 | AA34: 80 | AB34: =AA34-(J34+K34+L34+M34+N34+O34+P34+Q34+R34+S34+T34+U34+V34+W34+X34+Y34+Z34) -> 80 | AK34: =AB34-AC34-AD34-AE34-AF34-AG34-AH34-AI34-AJ34 -> 80
A35: 31 | B35: DIAZ ARENAS PEDRO FELIPE | C35: 75064983 | D35: Comunicación Social - Periodismo | E35: Ciencias Humanas | F35: Doctorado | G35: TC | H35: 40394 | I35: Titular | M35: 11.9 | N35: 15 | O35: 23 | P35: 8 | S35: 86.3 | T35: 4.7 | U35: 0 | V35: 8 | W35: 3 | X35: 1.5 | Y35: 0 | Z35: 23.9 | AA35: 540 | AB35: =AA35-(J35+K35+L35+M35+N35+O35+P35+Q35+R35+S35+T35+U35+V35+W35+X35+Y35+Z35) -> 354.7 | AK35: =AB35-AC35-AD35-AE35-AF35-AG35-AH35-AI35-AJ35 -> 354.7
A36: 32 | B36: GIRALDO MARIN LUCERO | C36: 25156982 | D36: Comunicación Social - Periodismo | E36: Ciencias Humanas | F36: Maestría | G36: TC | H36: 39664 | I36: Titular | J36: 13.5 | P36: 8 | Q36: 12 | R36: 3 | T36: 31.3 | U36: 0 | V36: 6.2 | W36: 16.7 | X36: 0 | Y36: 0 | Z36: 14.1 | AA36: 540 | AB36: =AA36-(J36+K36+L36+M36+N36+O36+P36+Q36+R36+S36+T36+U36+V36+W36+X36+Y36+Z36) -> 435.2 | AK36: =AB36-AC36-AD36-AE36-AF36-AG36-AH36-AI36-AJ36 -> 435.2
A37: 33 | B37: GRANADOS MORENO WILSON HORACIO | C37: 70081587 | D37: Comunicación Social - Periodismo | E37: Ciencias Humanas | F37: Doctorado | G37: TC | H37: 34171 | I37: Titular | J37: 63.9 | U37: 0 | V37: 0 | W37: 0 | X37: 0 | Y37: 0 | Z37: 0 | AA37: 540 | AB37: =AA37-(J37+K37+L37+M37+N37+O37+P37+Q37+R37+S37+T37+U37+V37+W37+X37+Y37+Z37) -> 476.1 | AK37: =AB37-AC37-AD37-AE37-AF37-AG37-AH37-AI37-AJ37 -> 476.1
A38: 34 | B38: LEAL LARRARTE SANDRA ADRIANA | C38: 52070041 | D38: Comunicación Social - Periodismo | E38: Ciencias Humanas | F38: Doctorado | G38: TC | H38: 38800 | I38: Titular | J38: 12 | L38: 21.1 | O38: 13.7 | P38: 12 | Q38: 12 | R38: 6 | S38: 25.4 | T38: 28.1 | U38: 0 | V38: 3.2 | W38: 35 | X38: 0 | Y38: 27 | Z38: 0 | AA38: 540 | AB38: =AA38-(J38+K38+L38+M38+N38+O38+P38+Q38+R38+S38+T38+U38+V38+W38+X38+Y38+Z38) -> 344.5 | AK38: =AB38-AC38-AD38-AE38-AF38-AG38-AH38-AI38-AJ38 -> 344.5
A39: 35 | B39: LOZANO BOTACHE JORGE PRUDENCIO | C39: 93357542 | D39: Comunicación Social - Periodismo | E39: Ciencias Humanas | F39: Doctorado | G39: TC | H39: 41673 | I39: Titular | O39: 26.4 | Q39: 6 | T39: 29.1 | U39: 0 | V39: 0 | W39: 18.5 | X39: 0 | Y39: 0 | Z39: 14.1 | AA39: 540 | AB39: =AA39-(J39+K39+L39+M39+N39+O39+P39+Q39+R39+S39+T39+U39+V39+W39+X39+Y39+Z39) -> 445.9 | AK39: =AB39-AC39-AD39-AE39-AF39-AG39-AH39-AI39-AJ39 -> 445.9
A40: 36 | B40: MEJÍA ESCOBAR BIBIANA MAGALY | C40: 25213746 | D40: Comunicación Social - Periodismo | E40: Ciencias Humanas | F40: Doctorado | G40: TC | H40: 42955 | I40: Asociado | R40: 16.1 | T40: 16.6 | U40: 0 | V40: 3 | W40: 0 | X40: 0 | Y40: 0 | Z40: 0 | AA40: 320 | AB40: =AA40-(J40+K40+L40+M40+N40+O40+P40+Q40+R40+S40+T40+U40+V40+W40+X40+Y40+Z40) -> 284.3 | AK40: =AB40-AC40-AD40-AE40-AF40-AG40-AH40-AI40-AJ40 -> 284.3
...

Sheet Puntos aprobados_2026
A1: Factores Salariales Decreto 1279, artículo 12 | B1: Productividad académica | C1: No. de productos | D1: Puntos asignados CIARP 01- 18/03/2026 | E1: Columna2 | F1: Columna3 | G1: Columna4 | H1: Total
A2: Título universitarios de pregrado y posgrado | D2: =Titulo!O3 -> 80 | H2: =SUM(Tabla6[[#This Row],[Puntos asignados CIARP 01- 18/03/2026]:[Columna3]]) -> 80
A3: Ascenso de categoría - escalafón docente | D3: =Ascenso_Categoria!K3+Ascenso_Categoria!K4+Ascenso_Categoria!K5+Ascenso_Categoria!K6+Ascenso_Categoria!K7+Ascenso_Categoria!K8 -> 102 | H3: =SUM(Tabla6[[#This Row],[Puntos asignados CIARP 01- 18/03/2026]:[Columna3]]) -> 102
A4: Productividad académica | B4: Revistas especializadas | D4: =Pub_Rev_Index!X4+Pub_Rev_Index!X7+Pub_Rev_Index!X9+Pub_Rev_Index!X10+Pub_Rev_Index!X12+Pub_Rev_Index!X13+Pub_Rev_Index!X15+Pub_Rev_Index!X18+Pub_Rev_Index!X21+Pub_Rev_Index!X22+Pub_Rev_Index!X24 -> 74.5 | H4: =SUM(Tabla6[[#This Row],[Puntos asignados CIARP 01- 18/03/2026]:[Columna3]]) -> 74.5
B5: Producción de videos, cinematográficas o fonográficas | H5: =SUM(Tabla6[[#This Row],[Puntos asignados CIARP 01- 18/03/2026]:[Columna3]]) -> 0
B6: Libros resultado de Investigación | H6: =SUM(Tabla6[[#This Row],[Puntos asignados CIARP 01- 18/03/2026]:[Columna3]]) -> 0
B7: Libros de Texto | H7: =SUM(Tabla6[[#This Row],[Puntos asignados CIARP 01- 18/03/2026]:[Columna3]]) -> 0
B8: Libros de Ensayo | D8: =Libro_Ensayo!S3 -> 10.425 | H8: =SUM(Tabla6[[#This Row],[Puntos asignados CIARP 01- 18/03/2026]:[Columna3]]) -> 10.425
B9: Premios Nacionales e internacionales | H9: =SUM(Tabla6[[#This Row],[Puntos asignados CIARP 01- 18/03/2026]:[Columna3]]) -> 0
B10: Patentes | H10: =SUM(Tabla6[[#This Row],[Puntos asignados CIARP 01- 18/03/2026]:[Columna3]]) -> 0
B11: Traducciones de libros | H11: =SUM(Tabla6[[#This Row],[Puntos asignados CIARP 01- 18/03/2026]:[Columna3]]) -> 0
B12: Obras Artísticas | H12: =SUM(Tabla6[[#This Row],[Puntos asignados CIARP 01- 18/03/2026]:[Columna3]]) -> 0
B13: Producción Técnica | H13: =SUM(Tabla6[[#This Row],[Puntos asignados CIARP 01- 18/03/2026]:[Columna3]]) -> 0
B14: Producción de Software | H14: =SUM(Tabla6[[#This Row],[Puntos asignados CIARP 01- 18/03/2026]:[Columna3]]) -> 0
A15: Actividades académico - administrativas | D15: =SUM(DAA!J4:J27) -> 99.5 | H15: =SUM(Tabla6[[#This Row],[Puntos asignados CIARP 01- 18/03/2026]:[Columna3]]) -> 99.5
A16: Desempeño destacado docente | D16: =SUM(DDD_Auxiliar!J4:J22,DDD_Asistente!J4:J26,DDD_Asociado!J4:J23,DDD_Titular!J4:J23) -> 281.3 | H16: =SUM(Tabla6[[#This Row],[Puntos asignados CIARP 01- 18/03/2026]:[Columna3]]) -> 281.3
A17: Experiencia Calificada | D17: =SUM(Exp_Calificada!J4:J265) -> 518 | H17: =SUM(Tabla6[[#This Row],[Puntos asignados CIARP 01- 18/03/2026]:[Columna3]]) -> 518
A18: Total | C18: =SUBTOTAL(109,Tabla6[No. de productos]) -> 0 | D18: =SUBTOTAL(109,Tabla6[Puntos asignados CIARP 01- 18/03/2026]) -> 1165.725 | E18: =SUBTOTAL(109,Tabla6[Columna2]) -> 0 | H18: =SUBTOTAL(109,Tabla6[Total]) -> 1165.725
A20: Total puntos Productividad académica | D20: =SUM(D4:D14) -> 84.925

Sheet Titulo
A2: AÑO | B2: SEMESTRE | C2: No. | D2: DOCUMENTO DE IDENTIDAD | E2: NOMBRE DEL DOCENTE | F2: ESCOLARIDAD ANTERIOR | G2: CATEGORÍA | H2: TIEMPO DE DEDICACIÓN | I2: PROGRAMA ACADÉMICO | J2: FACULTAD | K2: UNIVERSIDAD QUE OTORGA EL TÍTULO | L2: TITULO OTORGADO | M2: Acto de Convalidación (Para títulos Univ.del Ext.) | N2: FECHA GRADUACIÓN | O2: PUNTOS ASIGNADOS | P2: ACTA Y FECHA CIARP | Q2: OBSERVACIONES
A3: 2026 | B3: I | C3: 1 | D3: 1102042502 | E3: CRISTIAN CAMILO REYES GALEANO | F3: Doctorado | G3: Asistente | H3: TC | I3: Licenciatura en Lenguas Modernas con énfasis en Inglés y Francés | J3: Ciencias de la Educación | K3: Universidad de la Salle | L3: Doctor en Educación y Sociedad | M3: N/A | N3: 46003 | O3: 80 | P3: 1- 18/03/2026
L5: TOTAL PUNTOS TÍTULOS | O5: =SUM(O3:O4) -> 80
F8: __________________________________ | K8: _______________________________
F9: LINA MARCELA CRUZ CALDERÓN | K9: LUZ AMPARO CELIS BURITICÁ
F10: Técnico Oficina de Asuntos Profesorales | K10: Jefe Oficina Asuntos Profesorales y Secretaria Ejecutiva CIARP
F11: Proyectó y Elaboró | K11: Revisó

Sheet Ascenso_Categoria
A2: AÑO | B2: SEMESTRE | C2: No. | D2: IDENTIFICACIÓN | E2: NOMBRE DEL DOCENTE | F2: TIEMPO DE DEDICACIÓN | G2: PROGRAMA | H2: FACULTAD | I2: RES. DE APROBACIÓN C.E.I. o Acta de Aprob.CEI | J2: FECHA DE ASCENSO ( a partir de) | K2: PUNTOS ASIGNADOS | L2: CATEGORÍA APROBADA | M2: ACTA Y FECHA CIARP | N2: OBSERVACIONES
A3: 2026 | B3: I | C3: 1 | D3: 29226257 | E3: IVONNE CAICEDO GONZALEZ | F3: TC | G3: Administración Financiera | H3: Ciencias Económicas, Administrativas y Contables | I3: Acta. No.01 del 17/02/2026 | J3: 17 de febrero | K3: {=_xlfn.IFS(L3="Asistente", 21, L3="Asociado", 16, L3="Titular", 22)} -> 16 | L3: Asociado | M3: 1- 18/03/2026
A4: 2026 | B4: I | C4: 2 | D4: 41943016 | E4: CLAUDIA CONSTANZA CABAL CRUZ | F4: TC | G4: Contaduría Pública | H4: Ciencias Económicas, Administrativas y Contables | I4: Acta. No.01 del 17/02/2026 | J4: 17 de febrero | K4: {=_xlfn.IFS(L4="Asistente", 21, L4="Asociado", 16, L4="Titular", 22)} -> 16 | L4: Asociado | M4: 1- 18/03/2026
A5: 2026 | B5: I | C5: 3 | D5: 1094901176 | E5: DIEGO FERNANDO RAMÍREZ JIMÉNEZ | F5: TC | G5: Ingeniería Electrónica | H5: Ingeniería | I5: Acta. No.02 del 10/03/2026 | J5: 10 de marzo | K5: {=_xlfn.IFS(L5="Asistente", 21, L5="Asociado", 16, L5="Titular", 22)} -> 16 | L5: Asociado | M5: 1- 18/03/2026
A6: 2026 | B6: I | C6: 4 | D6: 1094885534 | E6: CARLOS ANDRÉS TABARES RAMÍREZ | F6: TC | G6: Licenciatura en Educación Física, Recreación y Deportes | H6: Ciencias de la Educación | I6: Acta. No.02 del 10/03/2026 | J6: 10 de marzo | K6: {=_xlfn.IFS(L6="Asistente", 21, L6="Asociado", 16, L6="Titular", 22)} -> 16 | L6: Asociado | M6: 1- 18/03/2026
A7: 2026 | B7: I | C7: 5 | D7: 1094882594 | E7: JHOJAN CARDONA PATIÑO | F7: TC | G7: Licenciatura en Educación Física, Recreación y Deportes | H7: Ciencias de la Educación | I7: Acta. No.02 del 10/03/2026 | J7: 10 de marzo | K7: {=_xlfn.IFS(L7="Asistente", 21, L7="Asociado", 16, L7="Titular", 22)} -> 16 | L7: Asociado | M7: 1- 18/03/2026
A8: 2026 | B8: I | C8: 6 | D8: 18399636 | E8: ALEXANDER LÓPEZ PARRADO | F8: TC | G8: Ingeniería Electrónica | H8: Ingeniería | I8: Acta. No.02 del 10/03/2026 | J8: 10 de marzo | K8: {=_xlfn.IFS(L8="Asistente", 21, L8="Asociado", 16, L8="Titular", 22)} -> 22 | L8: Titular | M8: 1- 18/03/2026
H10: TOTAL PUNTOS CAMBIO DE CATEGORÍA | K10: =SUM(K3:K9) -> 102
C13: __________________________________ | I13: _______________________________
C14: LINA MARCELA CRUZ CALDERÓN | I14: LUZ AMPARO CELIS BURITICÁ
C15: Técnico Oficina de Asuntos Profesorales | I15: Jefe Oficina Asuntos Profesorales y Secretaria Ejecutiva CIARP
C16: Proyectó y Elaboró | I16: Revisó

Sheet Pub_Rev_Index
A2: AÑO | B2: SEMESTRE | C2: No. | D2: TÍTULO ARTÍCULO | E2: MODALIDAD | F2: TIPO | G2: PAIS | H2: ISSN REVISTA | I2: NOMBRE REVISTA | J2: PUBLINDEX | K2: CATEGORÍA REVISTA | L2: NUMERO DE AUTORES | M2: EDITORIAL | N2: FECHA | Q2: DOCUMENTO DE IDENTIFICAC. | R2: NOMBRES DE AUTORES PERTENECIENTES A UNIVERSIDADES | S2: ESCOLARIDAD | T2: CATEGORÍA DEL DOCENTE | U2: TIEMPO DE DEDICACIÓN | V2: PROGRAMA | W2: FACULTAD | X2: PUNTAJE AUTOR | Y2: UNIVERSIDAD DE LOS AUTORES (PARTICIPANTES) | Z2: ACTA Y FECHA CIARP | AA2: OBSERVACIÓN
N3: RECIBIDO | O3: APROBADO | P3: PUBLICADO
A4: 2026 | B4: I | C4: 1 | D4: Evaluación de escenarios de inundación mediante herramientas hidrodinámicas y geoespaciales: el caso de estudio del río Bugalagrande, Colombia | E4: Full paper | F4: Nacional | G4: Colombia | H4: 1909-7735 | I4: Ciencia e Ingeniería Neogranadina | J4: https://scienti.minciencias.gov.co/publindex/#/revistasPublindex/detalle?tipo=R&idRevista=264 | K4: B | L4: 3 | M4: Universidad Militar Nueva Granada | N4: 45666 | O4: 45803 | P4: 45952 | Q4: 89007517 | R4: JULIÁN GARZÓN BARRERO | S4: Doctorado | T4: Asociado | U4: TC | V4: Ingeniería Topográfica y Geomática | W4: Ingeniería | X4: =IF(OR(K4="", L4=""), "", IF(K4="A1", 15, IF(K4="A2", 12, IF(K4="B", 8, IF(K4="C", 3, 0)))) / IF(L4<=3, 1, IF(L4<=5, 2, L4/2))) -> 8 | Y4: Universidad del Quindío | Z4: 1- 18/03/2026
A5: 2026 | B5: I | C5: 1 | R5: Nancy Estela Sánchez Pineda | X5: =IF(OR(K5="", L5=""), "", IF(K5="A1", 15, IF(K5="A2", 12, IF(K5="B", 8, IF(K5="C", 3, 0)))) / IF(L5<=3, 1, IF(L5<=5, 2, L5/2))) | Y5: Universidad del Quindío
A6: 2026 | B6: I | C6: 1 | R6: Juan Carlos González Valencia | X6: =IF(OR(K6="", L6=""), "", IF(K6="A1", 15, IF(K6="A2", 12, IF(K6="B", 8, IF(K6="C", 3, 0)))) / IF(L6<=3, 1, IF(L6<=5, 2, L6/2))) | Y6: Universidad del Quindío
A7: 2026 | B7: I | C7: 2 | D7: Integración de la Competencia Comunicativa Intercultural en la didáctica de lenguas extranjeras en Escuela Nueva | E7: Full paper | F7: Nacional de rotación internacional | G7: Colombia | H7: 2145-9444 | I7: Zona Próxima | J7: https://scienti.minciencias.gov.co/publindex/#/revistasPublindex/detalle?tipo=R&idRevista=882 | K7: B | L7: 2 | M7: Fundación Universidad del Norte | N7: 45476 | O7: 45633 | P7: 45848 | Q7: 1102042502 | R7: CRISTIAN CAMILO REYES GALEANO | S7: Doctorado | T7: Asistente | U7: TC | V7: Licenciatura en Lenguas Modernas con énfasis en Inglés y Francés | W7: Ciencias de la Educación | X7: =IF(OR(K7="", L7=""), "", IF(K7="A1", 15, IF(K7="A2", 12, IF(K7="B", 8, IF(K7="C", 3, 0)))) / IF(L7<=3, 1, IF(L7<=5, 2, L7/2))) -> 8 | Y7: Universidad del Quindío | Z7: 1- 18/03/2026
A8: 2026 | B8: I | C8: 2 | R8: María Camila Restrepo Neme | X8: =IF(OR(K8="", L8=""), "", IF(K8="A1", 15, IF(K8="A2", 12, IF(K8="B", 8, IF(K8="C", 3, 0)))) / IF(L8<=3, 1, IF(L8<=5, 2, L8/2))) | Y8: Universidad del Quindío
A9: 2026 | B9: I | C9: 3 | D9: Impacto inflacionario poscovid en Colombia (2020-2023): factores y consecuencias | E9: Full paper | F9: Nacional | G9: Colombia | H9: 2619-4244 | I9: Dictamen Libre | J9: https://scienti.minciencias.gov.co/publindex/#/revistasPublindex/detalle?tipo=R&idRevista=1044 | K9: C | L9: 3 | M9: Universidad Libre de Colombia | N9: 45464 | O9: 45730 | P9: 45765 | Q9: 89000647 | R9: ALEXANDER CASTRO DÍAZ | S9: Maestria | T9: Asistente | U9: TC | V9: Economía | W9: Ciencias Económicas, Administrativas y Contables | X9: =IF(OR(K9="", L9=""), "", IF(K9="A1", 15, IF(K9="A2", 12, IF(K9="B", 8, IF(K9="C", 3, 0)))) / IF(L9<=3, 1, IF(L9<=5, 2, L9/2))) -> 3 | Y9: Universidad del Quindío | Z9: 1- 18/03/2026
A10: 2026 | B10: I | C10: 3 | D10: Impacto inflacionario poscovid en Colombia (2020-2023): factores y consecuencias | E10: Full paper | F10: Nacional | G10: Colombia | H10: 2619-4244 | I10: Dictamen Libre | J10: https://scienti.minciencias.gov.co/publindex/#/revistasPublindex/detalle?tipo=R&idRevista=1044 | K10: C | L10: 3 | M10: Universidad Libre de Colombia | N10: 45464 | O10: 45730 | P10: 45765 | Q10: 89007946 | R10: CARLOS ANDRÉS GARCÍA GIRALDO | S10: Maestria | T10: Asistente | U10: TC | V10: Administración de Negocios | W10: Ciencias Económicas, Administrativas y Contables | X10: =IF(OR(K10="", L10=""), "", IF(K10="A1", 15, IF(K10="A2", 12, IF(K10="B", 8, IF(K10="C", 3, 0)))) / IF(L10<=3, 1, IF(L10<=5, 2, L10/2))) -> 3 | Y10: Universidad del Quindío | Z10: 1- 18/03/2026
A11: 2026 | B11: I | C11: 3 | R11: Jaime Aldana Diana Lucía | X11: =IF(OR(K11="", L11=""), "", IF(K11="A1", 15, IF(K11="A2", 12, IF(K11="B", 8, IF(K11="C", 3, 0)))) / IF(L11<=3, 1, IF(L11<=5, 2, L11/2))) | Y11: Universidad del Quindío
A12: 2026 | B12: I | C12: 4 | D12: Estrategia pedagógica: el aula invertida como innovación curricular en la formación de administradores financieros de la Universidad del Quindío, Colombia | E12: Full paper | F12: Nacional | G12: Colombia | H12: 2346-0806 | I12: Sophia | J12: https://scienti.minciencias.gov.co/publindex/#/revistasPublindex/detalle?tipo=R&idRevista=1017 | K12: B | L12: 3 | M12: Universidad La Gran Colombia Seccional Armenia | N12: 45566 | O12: 45901 | P12: 45953 | Q12: 89007946 | R12: CARLOS ANDRÉS GARCÍA GIRALDO | S12: Maestria | T12: Asistente | U12: TC | V12: Administración de Negocios | W12: Ciencias Económicas, Administrativas y Contables | X12: =IF(OR(K12="", L12=""), "", IF(K12="A1", 15, IF(K12="A2", 12, IF(K12="B", 8, IF(K12="C", 3, 0)))) / IF(L12<=3, 1, IF(L12<=5, 2, L12/2))) -> 8 | Y12: Universidad del Quindío | Z12: 1- 18/03/2026
A13: 2026 | B13: I | C13: 4 | D13: Estrategia pedagógica: el aula invertida como innovación curricular en la formación de administradores financieros de la Universidad del Quindío, Colombia | E13: Full paper | F13: Nacional | G13: Colombia | H13: 2346-0806 | I13: Sophia | J13: https://scienti.minciencias.gov.co/publindex/#/revistasPublindex/detalle?tipo=R&idRevista=1017 | K13: B | L13: 3 | M13: Universidad La Gran Colombia Seccional Armenia | N13: 45566 | O13: 45901 | P13: 45953 | Q13: 41916725 | R13: BERLY ROMAN VALENCIA | S13: Maestria | T13: Auxiliar | U13: TC | V13: Administración Financiera | W13: Ciencias Económicas, Administrativas y Contables | X13: =IF(OR(K13="", L13=""), "", IF(K13="A1", 15, IF(K13="A2", 12, IF(K13="B", 8, IF(K13="C", 3, 0)))) / IF(L13<=3, 1, IF(L13<=5, 2, L13/2))) -> 8 | Y13: Universidad del Quindío | Z13: 1- 18/03/2026
A14: 2026 | B14: I | C14: 4 | R14: Ivonne Caicedo González | X14: =IF(OR(K14="", L14=""), "", IF(K14="A1", 15, IF(K14="A2", 12, IF(K14="B", 8, IF(K14="C", 3, 0)))) / IF(L14<=3, 1, IF(L14<=5, 2, L14/2))) | Y14: Universidad del Quindío
A15: 2026 | B15: I | C15: 5 | D15: Multi-Output Gaussian Processes Applied to Modeling and Reducing Dimensionality of Data Transmitted in a Wireless Sensor Network | E15: Full paper | F15: Nacional | G15: Colombia | H15: 2357-5328 | I15: Revista Facultad de Ingeniería | J15: https://scienti.minciencias.gov.co/publindex/#/revistasPublindex/detalle?tipo=R&idRevista=861 | K15: B | L15: 3 | M15: Universidad Pedagógica y Tecnológica de Colombia | N15: 45561 | O15: 45669 | P15: 45825 | Q15: 89007291 | R15: PABLO ANDRÉS MUÑOZ GUTIERREZ | S15: Doctorado | T15: Asociado | U15: TC | V15: Tecnología en Instrumentación Electrónica | W15: Ciencias Básicas y Tecnologías | X15: =IF(OR(K15="", L15=""), "", IF(K15="A1", 15, IF(K15="A2", 12, IF(K15="B", 8, IF(K15="C", 3, 0)))) / IF(L15<=3, 1, IF(L15<=5, 2, L15/2))) -> 8 | Y15: Universidad del Quindío | Z15: 1- 18/03/2026
A16: 2026 | B16: I | C16: 5 | R16: José Aicardo Ortega Vela | X16: =IF(OR(K16="", L16=""), "", IF(K16="A1", 15, IF(K16="A2", 12, IF(K16="B", 8, IF(K16="C", 3, 0)))) / IF(L16<=3, 1, IF(L16<=5, 2, L16/2))) | Y16: Universidad del Quindío
A17: 2026 | B17: I | C17: 5 | R17: Hernán Darío Vargas Cardona | X17: =IF(OR(K17="", L17=""), "", IF(K17="A1", 15, IF(K17="A2", 12, IF(K17="B", 8, IF(K17="C", 3, 0)))) / IF(L17<=3, 1, IF(L17<=5, 2, L17/2))) | Y17: Universidad del Quindío
A18: 2026 | B18: I | C18: 6 | D18: La educación superior y el transito reflexivo hacia la realidad evaluativa | E18: Full paper | F18: Nacional | G18: Colombia | H18: 2346-0806 | I18: Sophia | J18: https://scienti.minciencias.gov.co/publindex/#/revistasPublindex/detalle?tipo=R&idRevista=1017 | K18: B | L18: 3 | M18: Universidad La Gran Colombia Seccional Armenia | N18: 44958 | O18: 45566 | P18: 45768 | Q18: 17655304 | R18: JUAN CARLOS SÁNCHEZ MUÑOZ | S18: Doctorado | T18: Titular | U18: TC | V18: Licenciatura en Educación Física, Recreación y Deportes | W18: Ciencias de la Educación | X18: =IF(OR(K18="", L18=""), "", IF(K18="A1", 15, IF(K18="A2", 12, IF(K18="B", 8, IF(K18="C", 3, 0)))) / IF(L18<=3, 1, IF(L18<=5, 2, L18/2))) -> 8 | Y18: Universidad del Quindío | Z18: 1- 18/03/2026
A19: 2026 | B19: I | C19: 6 | R19: Eliana Marcela Suarez Cárdenas | X19: =IF(OR(K19="", L19=""), "", IF(K19="A1", 15, IF(K19="A2", 12, IF(K19="B", 8, IF(K19="C", 3, 0)))) / IF(L19<=3, 1, IF(L19<=5, 2, L19/2))) | Y19: Universidad del Quindío
A20: 2026 | B20: I | C20: 6 | R20: Diana María García Cardona | X20: =IF(OR(K20="", L20=""), "", IF(K20="A1", 15, IF(K20="A2", 12, IF(K20="B", 8, IF(K20="C", 3, 0)))) / IF(L20<=3, 1, IF(L20<=5, 2, L20/2))) | Y20: Universidad del Quindío
A21: 2026 | B21: I | C21: 7 | D21: Diversidad familiar y familias ensambladas: reflexiones para desafiar el modelo nuclear hegemónico | E21: Full paper | F21: Nacional de rotación internacional | G21: Colombia | H21: 2665-3354 | I21: El Ágora USB | J21: https://scienti.minciencias.gov.co/publindex/#/revistasPublindex/detalle?tipo=R&idRevista=510 | K21: B | L21: 1 | M21: Universidad De San Buenaventura | N21: 45600 | O21: 45759 | P21: 45975 | Q21: 42144287 | R21: ANA MARÍA GIL RÍOS | S21: Doctorado | T21: Asociado | U21: TC | V21: Trabajo Social | W21: Ciencias Humanas | X21: =IF(OR(K21="", L21=""), "", IF(K21="A1", 15, IF(K21="A2", 12, IF(K21="B", 8, IF(K21="C", 3, 0)))) / IF(L21<=3, 1, IF(L21<=5, 2, L21/2))) -> 8 | Y21: Universidad del Quindío | Z21: 1- 18/03/2026
A22: 2026 | B22: I | C22: 8 | D22: Diseño de estrategias participativas para el desarrollo territorial en entidades de salud Caldas y Quindío / Design of participatory strategies for territorial development in health entities Caldas and Quindío | E22: Full paper | F22: Nacional de rotación internacional | G22: Colombia | H22: 2539-0279 | I22: Entramado | J22: https://scienti.minciencias.gov.co/publindex/#/revistasPublindex/detalle?tipo=R&idRevista=126 | K22: B | L22: 2 | M22: Universidad Libre de Colombia | N22: 45534 | O22: 45605 | P22: 45667 | Q22: 30320098 | R22: MARÍA BEATRIZ ESCOBAR ESCOBAR | S22: Doctorado | T22: Asociado | U22: TC | V22: Enfermería | W22: Ciencias de la Salud | X22: =IF(OR(K22="", L22=""), "", IF(K22="A1", 15, IF(K22="A2", 12, IF(K22="B", 8, IF(K22="C", 3, 0)))) / IF(L22<=3, 1, IF(L22<=5, 2, L22/2))) -> 8 | Y22: Universidad del Quindío | Z22: 1- 18/03/2026
A23: 2026 | B23: I | C23: 8 | R23: Ricardo Antonio Escobar | X23: =IF(OR(K23="", L23=""), "", IF(K23="A1", 15, IF(K23="A2", 12, IF(K23="B", 8, IF(K23="C", 3, 0)))) / IF(L23<=3, 1, IF(L23<=5, 2, L23/2))) | Y23: Escuela de Administración Publica ESAP
A24: 2026 | B24: I | C24: 9 | D24: Computational Thinking in the University Context: A Literature Review of Assessment Instruments | E24: Full paper | F24: Nacional | G24: Colombia | H24: 2256-5337 | I24: TecnoLógicas | J24: https://scienti.minciencias.gov.co/publindex/#/revistasPublindex/detalle?tipo=R&idRevista=605 | K24: B | L24: 3 | M24: Instituto Tecnológico Metropolitano de Medellín | N24: 45685 | O24: 45845 | P24: 45916 | Q24: 89004671 | R24: SERGIO AUGUSTO CARDONA TORRES | S24: Doctorado | T24: Titular | U24: TC | V24: Ingeniería de Sistemas y Computación | W24: Ingeniería | X24: 4.5 | Y24: Universidad del Quindío | Z24: 1- 18/03/2026 | AA24: Se asignan 4,5 de 8 puntos al profesor Sergio A. Cardona T, ya que el docente alcanzó el tope máximo de puntos en su categoría
A25: 2026 | B25: I | C25: 9 | R25: Angela María Muñoz Muñoz | X25: =IF(OR(K25="", L25=""), "", IF(K25="A1", 15, IF(K25="A2", 12, IF(K25="B", 8, IF(K25="C", 3, 0)))) / IF(L25<=3, 1, IF(L25<=5, 2, L25/2))) | Y25: Universidad del Quindío
A26: 2026 | B26: I | C26: 9 | R26: Milena Corrales Álvarez | X26: =IF(OR(K26="", L26=""), "", IF(K26="A1", 15, IF(K26="A2", 12, IF(K26="B", 8, IF(K26="C", 3, 0)))) / IF(L26<=3, 1, IF(L26<=5, 2, L26/2))) | Y26: Universidad del Quindío
A27: 2026 | B27: I | C27: 10 | D27: From error to insight: pedagical reflections on AI hallucinations and promt engineering | E27: Full paper | F27: Internacional | G27: China | H27: 1674-2974 | I27: Hunan Daxue Xuebao Journal Of Hunan University Natural Sciences | J27: https://scienti.minciencias.gov.co/publindex/#/revistasHomologadas/detalle/53148 | K27: No Homolagada | L27: 3 | M27: Journal of Hunan University | N27: 45970 | O27: 46024 | P27: 46052 | Q27: 18493676 | R27: JORGE ORLANDO HERRERA MORALES | S27: Maestria | T27: Asistente | U27: TC | V27: Ingeniería de Sistemas y Computación | W27: Ingeniería | X27: 0 | Y27: Universidad del Quindío | Z27: 1- 18/03/2026 | AA27: El artículo fue publicado en el año 2026, no cumple con lo establecido en el numeral 2 del artículo segundo del A.C.S No.012. Cada profesor someterá a consideración los resultados de su producción académica concluida durante el año calendario inmediatamente anterior.
A28: 2026 | B28: I | C28: 10 | D28: From error to insight: pedagical reflections on AI hallucinations and promt engineering | E28: Full paper | F28: Internacional | G28: China | H28: 1674-2974 | I28: Hunan Daxue Xuebao Journal Of Hunan University Natural Sciences | J28: https://scienti.minciencias.gov.co/publindex/#/revistasHomologadas/detalle/53148 | K28: No Homolagada | L28: 3 | M28: Journal of Hunan University | N28: 45970 | O28: 46024 | P28: 46052 | Q28: 9730805 | R28: JORGE ALEJANDRO ALDANA GUTIÉRREZ | S28: Maestría | T28: Asistente | U28: TC | V28: Ingeniería | W28: Ingeniería | X28: 0 | Y28: Universidad del Quindío | Z28: 1- 18/03/2026 | AA28: El artículo fue publicado en el año 2026, no cumple con lo establecido en el numeral 2 del artículo segundo del A.C.S No.012. Cada profesor someterá a consideración los resultados de su producción académica concluida durante el año calendario inmediatamente anterior.
A29: 2026 | B29: I | C29: 10 | R29: Darío Fernando Londoño Pinilla | Y29: Universidad del Quindío
A30: 2027 | B30: I | C30: 11
A31: 2028 | B31: I
A32: 2029 | B32: I
A33: 2030 | B33: I
A34: 2026 | B34: I | X34: =IF(OR(K34="", L34=""), "", IF(K34="A1", 15, IF(K34="A2", 12, IF(K34="B", 8, IF(K34="C", 3, 0)))) / IF(L34<=3, 1, IF(L34<=5, 2, L34/2)))
T36: TOTAL PUNTOS PUB. REV. INDEXADA | X36: =SUM(X4:X35) -> 74.5
I39: __________________________________ | S39: _______________________________
I40: LINA MARCELA CRUZ CALDERÓN | S40: LUZ AMPARO CELIS BURITICÁ
I41: Técnico Oficina Asuntos Profesorales | S41: Jefe Oficina Asuntos Profesorales y Secretaria Ejecutiva CIARP
I42: Proyectó y Elaboró | S42: Revisó

Sheet Libro_Ensayo
A2: AÑO | B2: SEMESTRE | C2: No. | D2: NOMBRE DEL LIBRO ENSAYO | E2: ISBN | F2: FECHA DE PUBLICACIÓN | G2: EDITORIAL | H2: DOCUMENTO DE IDENTIFICACIÓN | I2: AUTORES | J2: ESCOLARIDAD | K2: CATEGORÍA | L2: TIEMPO DE DEDICACIÓN | M2: PROGRAMA ACADÉMICO | N2: FACULTAD | O2: UNIVERSIDAD. PARTICIPANT | P2: PAR EVALUADOR MINCIENCIAS 1 | Q2: PAR EVALUADOR MINCIENCIAS 2 | R2: NUMERO DE AUTORES | S2: PUNTOS ASIGNADOS | T2: ACTA Y FECHA CIARP | U2: OBSERVACIONES
A3: 2026 | B3: I | C3: 1 | D3: Planeación laboral. Estrategia financiera para emprendedores y empresarios | E3: 978-628-7783-32-4 | F3: 45646 | G3: Kinesis Ltda | H3: 24573858 | I3: CONSTANZA LORETH FAJARDO CALDERON | J3: Maestría | K3: Titular | L3: TC | M3: Contaduría Pública | N3: Ciencias Económicas, Administrativas y Contables | O3: Universidad del Quindío | P3: =AVERAGE(3,2,3,1) -> 2.25 | Q3: =AVERAGE(4.5,4.7,4.8,4.8) -> 4.7 | R3: 3 | S3: =(AVERAGE(P3, Q3)*3) / IF(R3<=3, 1, IF(R3<=5, 2, R3/2)) -> 10.425 | T3: 1- 18/03/2026
A4: 2026 | B4: I | C4: 1 | I4: Santa Fajardo, Laura Michel | O4: Universidad de Manizales
A5: 2026 | B5: I | C5: 1 | I5: Santa Fajardo, Magda del Pilar | O5: Universidad del Quindío
N7: TOTAL PUNTOS LIBROS ENSAYO | S7: =SUM(S3:S6) -> 10.425
F10: _________________________________ | L10: __________________________________
F11: LINA MARCELA CRUZ CALDERÓN | L11: LUZ AMPARO CELIS BURITICÁ
F12: Técnico Oficina de Asuntos Profesorales | L12: Jefe Oficina Asuntos Profesorales y Secretaria Ejecutiva CIARP
F13: Proyectó y Elaboró | L13: Revisó

Sheet Prod_Videos
A2: AÑO | B2: SEMESTRE | C2: No. | D2: NOMBRE DE LA PROD. AUDIOVISUAL | E2: TIPO | F2: APORTE AUDIOVISAL | G2: IMPÁCTO | H2: DURACIÓN DE LA EMISIÓN Y AÑO DE PRODUCCIÓN | I2: ENTIDAD DIFUSORA QUE CERTIFICA | J2: DOCUMENTO DE IDENTIFICACIÓN | K2: AUTORES | L2: ESCOLARIDAD | M2: CATEGORÍA | N2: TIEMPO DE DEDICACIÓN | O2: PROGRAMA ACADÉMICO | P2: FACULTAD | Q2: UNIVERSIDAD. PARTICIPANT | R2: PUNTOS EVALUACIÓN PARES MINCIENCIAS | S2: PUNTOS ASIGNADOS | T2: ACTA Y FECHA CIARP | U2: OBSERVACIONES
A3: 2025 | B3: I | C3: 1 | D3: Podcast Común-mente, Lectura Dramática | E3: Digital | F3: Autoría del Contenido y Realizador, Director o Productor Técnico | G3: Internacional Documental | H3: 26 minutos, 57 segundos 2024 | I3: La Ufm estéreo | J3: 1094878677 | K3: ANDRÉS MAURICIO HERNÁNDEZ CARVAJAL | L3: Maestría | M3: Asistente | N3: TC | O3: Ciencia de la Información y la Documentación, Bibliotecología y Archivística | P3: Ciencias Humanas y Bellas Artes | Q3: Universidad del Quindío | R3: Eval.1= 12 Eval.2= 9,32 X=10,66 10,66*80%= 8,5 | S3: 8.5 | T3: 2- 23/04/2025 | U3: 3 Autores Decreto 1279 de 2002, artículo 10, numeral I, literal b "Los videos, cinematográficas o fonográficas realizadas con carácter documental tienen como tope, en cada caso, hasta el ochenta por ciento (80%) de lo señalado anteriormente" Al docente Jorge Eduardo Urrea Giraldo le fue aprobada la producción audiovisual en el CIARP 1 del 27/02/2025
K4: Jorge Eduardo Urrea Giraldo | Q4: Universidad del Quindío
K5: Camilo Andrés López Leal | Q5: Universidad del Quindío
O7: Total Puntos por Producción Audiovisual | S7: =SUM(S3:S6) -> 8.5
G12: __________________________________ | M12: _______________________________
G13: LINA MARCELA CRUZ CALDERÓN | M13: LUZ AMPARO CELIS BURITICÁ
G14: Técnico Oficina de Asuntos Profesorales | L14: Jefe Oficina Asuntos Profesorales y Secretaria Ejecutiva CIARP
G15: Proyectó y Elaboró | M15: Revisó

Sheet Libro_Res_Investigacion
A2: AÑO | B2: SEMESTRE | C2: No. | D2: NOMBRE DEL LIBRO | E2: ISBN | F2: FECHA DE PUBLICACIÓN | G2: EDITORIAL | H2: DOCUMENTO DE IDENTIFICACIÓN | I2: AUTORES | J2: ESCOLARIDAD | K2: CATEGORÍA | L2: TIEMPO DE DEDICACIÓN | M2: PROGRAMA ACADÉMICO | N2: FACULTAD | O2: UNIVERSIDAD. PARTICIPANT | P2: PAR EVALUADOR MINCIENCIAS 1 | Q2: PAR EVALUADOR MINCIENCIAS 2 | R2: NUMERO DE AUTORES | S2: PUNTOS ASIGNADOS | T2: ACTA Y FECHA CIARP | U2: OBSERVACIONES
A3: 2026 | B3: I | C3: 1 | D3: Disonancias del paisaje: análisis socioecosistémico del paisaje cultural cafetero | E3: 978-628-7699-94-6 | F3: 45526 | G3: Kinesis Ltda | H3: 52079098 | I3: LIGIA JANNETH MOLINA RICO | J3: Doctorado | K3: Asociado | L3: TC | M3: Licenciatura en Biología y Educación Ambiental | N3: Ciencias de la Educación | O3: Universidad del Quindío | P3: =AVERAGE(3,2,3,1,2) -> 2.2 | Q3: =AVERAGE(4.5,4.7,4.8,4.8,5) -> 4.76 | R3: 4 | S3: =(AVERAGE(P3, Q3)*4) / IF(R3<=3, 1, IF(R3<=5, 2, R3/2)) -> 6.96 | T3: 3- 30/05/2025 | U3: Artículo "Concepciones de los profesores sobre la enseñanza del uso sostenible del agua en educación media. El Paujil Caquetá, Amazonia Colombiana", Categoría B. Los puntos se pagarán a la docente Ligia Janneth Molina R. al término de la comisión académica-administrativa como decana de la Facultad de Ciencias de la Educación.
A4: 2026 | B4: I | C4: 1 | D4: Disonancias del paisaje: análisis socioecosistémico del paisaje cultural cafetero | E4: 978-628-7699-94-6 | F4: 45526 | G4: Kinesis Ltda | H4: 79567036 | I4: LEONARDO IVÁN QUINTANA URREA | J4: Maestría | K4: Asociado | L4: TC | M4: Trabajo Social | N4: Ciencias Humanas y Bellas Artes | O4: Universidad del Quindío | P4: =AVERAGE(3,2,3,1,2) -> 2.2 | Q4: =AVERAGE(4.5,4.7,4.8,4.8,5) -> 4.76 | R4: 4 | S4: =(AVERAGE(P4, Q4)*4) / IF(R4<=3, 1, IF(R4<=5, 2, R4/2)) -> 6.96 | T4: 3- 30/05/2025
A5: 2026 | B5: I | C5: 1 | D5: Disonancias del paisaje: análisis socioecosistémico del paisaje cultural cafetero | E5: 978-628-7699-94-6 | F5: 45526 | G5: Kinesis Ltda | H5: 24580571 | I5: ALBA LEONILDE SUAREZ ARIAS | J5: Doctorado | K5: Titular | L5: TC | M5: Trabajo Social | N5: Ciencias Humanas y Bellas Artes | O5: Universidad del Quindío | P5: =AVERAGE(3,2,3,1,2) -> 2.2 | Q5: =AVERAGE(4.5,4.7,4.8,4.8,5) -> 4.76 | R5: 4 | S5: =(AVERAGE(P5, Q5)*4) / IF(R5<=3, 1, IF(R5<=5, 2, R5/2)) -> 6.96 | T5: 3- 30/05/2025
I6: Norberto Marín Clavijo
O8: LIBROS PROD. INVESTIGACIÓN | S8: =SUM(S3:S7) -> 20.88
D11: __________________________________ | O11: ___________________________________
D12: LINA MARCELA CRUZ CALDERÓN | O12: _______________________________
D13: Técnico Oficina Asuntos Profesorales | O13: LUZ AMPARO CELIS BURITICÁ
D14: Proyectó y Elaboró | N14: Jefe Oficina Asuntos Profesorales y Secretaria Ejecutiva CIARP
O15: Revisó

Sheet Libro_Texto
A2: AÑO | B2: SEMESTRE | C2: No. | D2: NOMBRE DEL LIBRO TEXTO | E2: ISBN | F2: FECHA DE PUBLICACIÓN | G2: EDITORIAL | H2: ESPACIO ACADÉMICO | I2: DOCUMENTO DE IDENTIFICACIÓN | J2: AUTORES | K2: ESCOLARIDAD | L2: CATEGORÍA | M2: TIEMPO DE DEDICACIÓN | N2: PROGRAMA ACADÉMICO | O2: FACULTAD | P2: UNIVERSIDAD. PARTICIPANT | Q2: PAR EVALUADOR MINCIENCIAS 1 | R2: PAR EVALUADOR MINCIENCIAS 2 | S2: NUMERO DE AUTORES | T2: PUNTOS ASIGNADOS | U2: ACTA Y FECHA CIARP | V2: OBSERVACIONES
A3: 2025 | B3: I | C3: 1 | D3: Mercados financieros en el ámbito organizacional | E3: 978-628-7783-11-9 | F3: 45625 | G3: Kinesis Ltda | H3: Mercados Financieros | I3: 24580998 | J3: MARÍA CONSTANZA DÍAZ CRUZ | K3: Maestría | L3: Asociado | M3: TC | N3: Contaduría Pública | O3: Ciencias Económicas, Administrativas y Contables | P3: Universidad del Quindío | Q3: =AVERAGE(3,2,3,1) -> 2.25 | R3: =AVERAGE(4.5,4.7,4.8,4.8) -> 4.7 | S3: 5 | T3: =(AVERAGE(Q3, R3)*3) / IF(S3<=3, 1, IF(S3<=5, 2, S3/2)) -> 5.2125 | U3: 3- 30/05/2025
J4: Yaneth Ladino Villegas | P4: Universidad del Quindío
J5: Valeria Rivera Quiguanás | P5: Universidad del Quindío
A6: 2025 | B6: I | C6: 2 | D6: Generalidades del impuesto de renta de personas naturales en Colombia | E6: 978-628-7783-02-7 | F6: 45625 | G6: Kinesis Ltda | H6: Contabilidad Financiera I | I6: 9728326 | J6: RUBEN ANTONIO VÉLEZ RAMÍREZ | K6: Maestría | L6: Asistente | M6: TC | N6: Contaduría Pública | O6: Ciencias Económicas, Administrativas y Contables | P6: Universidad del Quindío | Q6: =AVERAGE(3,2,3,1) -> 2.25 | R6: =AVERAGE(4.5,4.7,4.8,4.8) -> 4.7 | S6: 8 | T6: =(AVERAGE(Q6, R6)*3) / IF(S6<=3, 1, IF(S6<=5, 2, S6/2)) -> 2.60625 | U6: 3- 30/05/2025
J7: Leidy Johanna Ramírez Ramírez | P7: Universidad del Quindío
J8: Lina María López Castañeda | P8: Universidad del Quindío
A9: 2025 | B9: I | C9: 3 | D9: De cero a económico: Explorando la economía | E9: 978-628-7783-03-4 | F9: 45625 | G9: Kinesis Ltda | H9: Microeconomia | I9: 89007946 | J9: CARLOS ANDRÉS GARCÍA GIRALDO | K9: Maestría | L9: Asistente | M9: TC | N9: Administración de Negocios | O9: Ciencias Económicas, Administrativas y Contables | P9: Universidad del Quindío | Q9: =AVERAGE(3,2,3,1) -> 2.25 | R9: =AVERAGE(4.5,4.7,4.8,4.8) -> 4.7 | S9: 11 | T9: =(AVERAGE(Q9, R9)*3) / IF(S9<=3, 1, IF(S9<=5, 2, S9/2)) -> 1.8954545 | U9: 3- 30/05/2025
J10: María Julieta Sánchez Mora | P10: Universidad del Quindío
J11: Dora Luz Álvarez García | P11: Universidad del Quindío
O13: TOTAL PUNTOS LIBROS TEXTO | T13: =SUM(T3:T12) -> 9.7142045
F16: __________________________________ | L16: _______________________________
F17: LINA MARCELA CRUZ CALDERÓN | M17: LUZ AMPARO CELIS BURITICÁ
F18: Técnico Oficina de Asuntos Profesorales | L18: Jefe Oficina Asuntos Profesorales y Secretaria Ejecutiva CIARP
F19: Proyectó y Elaboró | M19: Revisó

Sheet Premios
A2: AÑO | B2: SEMESTRE | C2: No. | D2: DOCUMENTO DE IDENTIFICACIÓN | E2: NOMBRE DEL DOCENTE | F2: ESCOLARIDAD | G2: CATEGORÍA | H2: TIEMPO DE DEDICACIÓN | I2: PROGRAMA ACADÉMICO | J2: FACULTAD | K2: TÍTULO DEL TRABAJO | L2: PREMIO O DISTINCIÓN | M2: ENTIDAD QUE OTORGA EL PREMIO | N2: FECHA OTORGAN PREMIO | O2: PUNTOS ASIGNADOS | P2: ACTA Y FECHA CIARP | Q2: OBSERVACIONES
A3: 2025 | B3: I | C3: 1 | D3: 46373917 | E3: ANA PATRICIA PÉREZ SAAVEDRA | F3: Maestría | G3: Asistente | H3: TC | I3: Enfermería | J3: Ciencias de la Salud | K3: Violencia simbólica y la enseñanza de enfermería en educación superior: Revisión sistemática exploratoria | L3: Tercer lugar de la categoría de Maestría: ponencia en modalidad de video | M3: Universidad de Sonora, Facultad Interdisciplinaria de Ciencias Biológicas y en Salud Departamento de Enfermería | N3: 19 de abril de 2024 | O3: 0 | P3: 3- 30/05/2025 | Q3: 2 Autores No cumple con lo establecido en el Decreto 1279 de 2002, artículo 24, numeral I, ítem g) Premio Nacionales e Internacionales. En los soportes no se evidencia la convocatoria publica a premio. Se adjunta el concepto del Grupo de Seguimiento al 1279 a la consulta 2021-ER-273316 que cita "Se aclara que, los reconocimientos a trabajos presentados en el marco de eventos académicos no corresponden a premios o distinciones salvo que cumplan los requisitos establecidos por el decreto, en especial, el reconocido prestigio de la institución otorgante y la existencia de una convocatoria de carácter nacional o internacional a participar por el premio o distinción (que no necesariamente coincide con la convocatoria a presentar trabajos en dicho evento académico) lo mismo que la claridad en su proceso de selección.”
E4: José Enver Ayala Zuluaga
L6: TOTAL PUNTOS PREMIOS | O6: =SUM(O3:O5) -> 0
F9: __________________________________ | K9: _______________________________
F10: LINA MARCELA CRUZ CALDERÓN | K10: LUZ AMPARO CELIS BURITICÁ
F11: Técnico Oficina de Asuntos Profesorales | K11: Jefe Oficina Asuntos Profesorales y Secretaria Ejecutiva CIARP
F12: Proyectó y Elaboró | K12: Revisó

Sheet Patentes
A2: AÑO | B2: SEMESTRE | C2: No. | D2: IDENTIFICACIÓN DEL AUTOR | E2: NOMBRES DE AUTORES PERTENECIENTES A UNIVERSIDADES | F2: PROGRAMA ACADÉMICO | G2: FACULTAD | H2: Tipo de producto | I2: Tipo de patente | J2: Nombre del producto | K2: Número de registro de la patente | L2: Fecha de aprobación de la patente | M2: Vigencia en años del producto | N2: Banco de patentes o entidad que expide el registro | O2: NUMERO DE AUTORES | P2: PUNTOS ASIGNADOS | Q2: ACTA Y FECHA CIARP | R2: OBSERVACIONES
A3: 2026 | B3: I | C3: 1 | D3: 16356361 | E3: HERNANDO CORREA GALLEGO | F3: Instituto Interdisciplinario de las Ciencias | G3: Ciencias Básicas y Tecnologías | H3: Patente de Invención | I3: De producto | J3: PROCESO DE FABRICACIÓN DE UNA PELÍCULA DE AISLAMIENTO ELÉCTRONICO BASADA EN ÓXIDOS DE COBRE PARA RECUBRIMIENTOS DE COBRE | K3: Res.No.13590 Ref. Expediente No. NC2019/0005187 | L3: 18 de marzo de 2022 | M3: 20 años | N3: Superintendencia de Industria y Comercio. | O3: 2 | P3: 0 | Q3: 3- 30/03/2023
A4: 2026 | B4: I | C4: 1 | D4: 41885303 | E4: LILIANA DEL SOCORRO TIRADO MEJÍA | F4: Instituto Interdisciplinario de las Ciencias | G4: Ciencias Básicas y Tecnologías | H4: Patente de Invención | I4: De producto | J4: PROCESO DE FABRICACIÓN DE UNA PELÍCULA DE AISLAMIENTO ELÉCTRONICO BASADA EN ÓXIDOS DE COBRE PARA RECUBRIMIENTOS DE COBRE | K4: Res.No.13590 Ref. Expediente No. NC2019/0005187 | L4: 18 de marzo de 2022 | M4: 20 años | N4: Superintendencia de Industria y Comercio. | O4: 2 | P4: 0 | Q4: 3- 30/03/2023
M6: TOTAL PUNTOS PATENTES | P6: =SUM(P3:P5) -> 0

Sheet Obras_Artisticas
A2: AÑO | B2: SEMESTRE | C2: No. | D2: NOMBRE DE LA OBRA ARTÍSTICA | E2: TIPO | F2: RECONOCIMIENTO SOLICITADO | G2: IMPÁCTO | H2: FECHA DE CREACIÓN DE LA OBRA / FECHA DE EXPOSICIÓN | I2: TÉCNICA UTILIZADA | J2: DOCUMENTO DE IDENTIFICACIÓN | K2: AUTORES | L2: ESCOLARIDAD | M2: CATEGORÍA | N2: TIEMPO DE DEDICACIÓN | O2: PROGRAMA ACADÉMICO | P2: FACULTAD | Q2: UNIVERSIDAD. PARTICIPANT | R2: PUNTOS EVALUACIÓN PARES MINCIENCIAS | S2: PUNTOS ASIGNADOS | T2: ACTA Y FECHA CIARP | U2: OBSERVACIONES
A3: 2025 | B3: I | C3: 1 | D3: Dimensiones | E3: Artes plásticas | F3: Creación original individual | G3: Internacional | H3: 10 al 15 de septiembre de 2024 | I3: Fotografía Dimensional | J3: 89004182 | K3: JORGE EDUARDO URREA GIRALDO | L3: Doctorado | M3: Asistente | N3: TC | O3: Comunicación Social - Periodismo | P3: Ciencias Humanas y Bellas Artes | Q3: Universidad del Quindío | R3: Eval.1= 4,0 Eval.2= 4,75 X= 4,375 X=4,375*4,0= 17,5 | S3: 0 | T3: 3- 30/05/2025 | U3: 1 Autor Al docente Jorge E. Urrea G. solo se le asignan 2.1 de 17.5 puntos, ya que alcanzó el tope máximo de puntos en su categoría de acuerdo a lo establecido en A.C.S 012 de 2009, Artículo Décimo
P5: TOTAL PUNTOS OBRA ARTISTICA | S5: =SUM(S3:S3) -> 0
G8: __________________________________ | L8: _______________________________
G9: LINA MARCELA CRUZ CALDERÓN | M9: LUZ AMPARO CELIS BURITICÁ
G10: Técnico Oficina de Asuntos Profesorales | L10: Jefe Oficina Asuntos Profesorales y Secretaria Ejecutiva CIARP
G11: Proyectó y Elaboró | M11: Revisó

Sheet Prod_Tecnica
A2: AÑO | B2: SEMESTRE | C2: No. | D2: NOMBRE DE LA PROUCCIÓN TÉCNICA | E2: TIPO DE PRODUCCIÓN | F2: AÑO DE PUBLICACIÓN | G2: DOCUMENTO DE IDENTIDAD | H2: AUTORES | I2: ESCOLARIDAD | J2: CATEGORÍA | K2: TIEMPO DE DEDICACIÓN | L2: PROGRAMA ACADÉMICO | M2: FACULTAD | N2: UNIVERSIDADES PARTICIPANTES | O2: PUNTOS EVALUACIÓN PARES MINCIENCIAS | P2: PUNTAJE ASIGNADO/ AUTOR | Q2: ACTA Y FECHA | R2: OBSERVACIÓN
A3: 2026 | B3: I | C3: 1 | D3: Construcción de un colector cilíndrico parabólico para el aprovechamiento de la energía solar | E3: Adaptación Tecnológica | F3: 2024 | G3: 89001325 | H3: CARLOS ANDRÉS CÁRDENAS VALENCIA | I3: Maestría | J3: Asociado | K3: TC | L3: Tecnología en Instrumentación Electrónica | M3: Ciencias Básicas y Tecnológias | N3: Universidad del Quindío | O3: Eval.1= 4,5 Eval.2= 3,94782609 X=8,44782609/2=4,2239 ≈4,2 | P3: 0 | Q3: 6- 29/08/2025 | R3: 3 Autores El calculo se realizó con base en la escala de calificación aprobada por el CIARP en el Acta No.6 de 2022 y con la escala de calificación (10) de la Res.00693 del 2004 de Minciencias. El resultado de la evaluación (4,2 puntos), no cumple con el puntaje de calidad que debe ser igual o superior al 60% (4,8 puntos) de la calificación máxima (8 puntos) para este producto académico, según lo acordado por el CIARP en el Acta 07 del 26/10/2016 como puntaje de calidad.
A4: 2026 | B4: I | C4: 1 | D4: Construcción de un colector cilíndrico parabólico para el aprovechamiento de la energía solar | E4: Adaptación Tecnológica | F4: 2024 | G4: 89007291 | H4: PABLO ANDRÉS MUÑOZ GUTIÉRREZ | I4: Doctorado | J4: Asociado | K4: TC | L4: Tecnología en Instrumentación Electrónica | M4: Ciencias Básicas y Tecnológias | N4: Universidad del Quindío | P4: 0
A5: 2026 | B5: I | C5: 1 | D5: Construcción de un colector cilíndrico parabólico para el aprovechamiento de la energía solar | E5: Adaptación Tecnológica | F5: 2024 | G5: 1094901176 | H5: DIEGO FERNANDO RAMÍREZ JIMÉNEZ | I5: Maestría | J5: Asistente | K5: TC | L5: Ingeniería Electrónica | M5: Ingeniería | N5: Universidad del Quindío | P5: 0
L7: TOTAL PUNTOS PRODUCCIÓN TÉCNICA | P7: =SUM(P3:P6) -> 0
F10: __________________________________ | K10: _______________________________
F11: LINA MARCELA CRUZ CALDERÓN | K11: LUZ AMPARO CELIS BURITICÁ
F12: Técnico Oficina de Asuntos Profesorales | K12: Jefe Oficina Asuntos Profesorales y Secretaria Ejecutiva CIARP
F13: Proyectó y Elaboró | K13: Revisó

Sheet Prod_Software
A2: AÑO | B2: SEMESTRE | C2: No. | D2: Identificación Libro/tomo/partida | E2: NOMBRE DEL SOFTWARE | F2: AÑO DE PUBLICACIÓN | G2: Documento de Identidad Autor-Docente | H2: AUTORES | I2: ESCOLARIDAD | J2: CATEGORÍA | K2: TIEMPO DE DEDICACIÓN | L2: PROGRAMA ACADÉMICO | M2: FACULTAD | N2: UNIVERSIDADES PARTICIPANTES | O2: PUNTAJE EVALUADORES | P2: PUNTAJE ASIGNADO/AUTOR (Escala 0 a 15) | Q2: ACTA Y FECHA | R2: OBSERVACIÓN
A3: 2025 | B3: II | C3: 1 | D3: 13-101-333 | E3: MMTOOL | F3: 45642 | G3: 16786435 | H3: WILLIAM JOSEPH GIRALDO OROZCO | I3: Doctorado | J3: Titular | K3: TC | L3: Ingeniería de Sistemas y Computación | M3: Ingeniería | N3: Universidad del Quindío | O3: Eval.1= 4,1 Eval.2= 4,37 X=4,235*3 = 12,705 ≈12,7 | P3: 12.7 | Q3: 7- 29/10/2025 | R3: 3 Autores Software de producción científica con generación de conocimiento
G4: 41948277 | H4: MARÍA LILI VILLEGAS RAMÍREZ | I4: Doctorado | J4: Titular | K4: TC | L4: Ingeniería de Sistemas y Computación | M4: Ingeniería | N4: Universidad del Quindío | P4: 12.7
G5: 41948811 | H5: ALEXANDRA RUIZ GAONA | I5: Doctorado | J5: Titular | K5: TC | L5: Ingeniería de Sistemas y Computación | M5: Ingeniería | N5: Universidad del Quindío | P5: 12.7
M7: TOTAL PUNTOS SOFTWARE | P7: =SUM(P3:P6) -> 38.1
E10: ________________________________ | M10: _______________________________
E11: LINA MARCELA CRUZ CALDERÓN | M11: LUZ AMPARO CELIS BURITICÁ
E12: Técnico Oficina Asuntos Profesorales | N12: Jefe Oficina Asuntos Profesorales y Secretaria Ejecutiva CIARP
E13: Proyectó y Elaboró | N13: Revisó

Sheet DAA
A1: OFICINA DE ASUNTOS PROFESORALES
A2: DESEMPEÑO ACADÉMICO - ADMINISTRATIVO 2025
A3: No. | B3: PROGRAMA | C3: DOC. DE IDENTIFICACIÓN | D3: NOMBRE | E3: FECHA DE INGRESO | F3: NIVEL DE FORMACIÓN | G3: CATEGORÍA | H3: RESULTADO EVALUACIÓN DOCENTE | I3: FECHA DE LA ULTIMA EVALUACIÓN | J3: PUNTOS POR DAA | K3: ESTADO | L3: OBSERVACIONES
A4: 1 | B4: Administración Financiera | C4: 29332068 | D4: ARRUBLA FRANCO MARIBETH | E4: 40203 | F4: Doctorado | G4: Titular | H4: 4.99 | I4: II/2025 | J4: 1.3 | K4: Academico-Administrativo | L4: Inició comisión académico-admon el 07/05/2025 como Directora del Programa de Administración Financiera (DAA 239/365*2= 1,30→ Total puntos= 1,3)
A5: 2 | B5: Biología | C5: 24675452 | D5: GIRALDO GARCÍA ALEJANDRA MARÍA | E5: 42955 | F5: Maestría | G5: Asistente | H5: 5 | I5: II/2025 | J5: 9 | K5: Academico-Administrativo | L5: Inició comisión académico-admon el 02/05/2023 como Vicerrectora de Extensión y Desarrollo Social
A6: 3 | B6: Contaduría Pública | C6: 328307 | D6: SIERRA PRIETO REINALDO | E6: 35828 | F6: Maestría | G6: Asistente | H6: 4.75 | I6: II/2025 | J6: 6 | K6: Cargo Academico-Administrativo | L6: Inició comisión académico-admon el 01/06/2023 como Decano de la Facultad de Ciencias Economicas
A7: 4 | B7: Economía | C7: 36310363 | D7: FLOREZ LAISECA ADRIANA MARÍA | E7: 42955 | F7: Maestría | G7: Asociado | H7: 4.77 | I7: II/2024 | J7: 2 | K7: Cargo Académico Adtivo | L7: Inició comisión académico-admon el 01/06/2023 como Directora del Programa de Economía
A8: 5 | B8: Física | C8: 70420310 | D8: GÓMEZ GONZÁLEZ EDGAR ARTURO | E8: 40973 | F8: Doctorado | G8: Asociado | H8: 5 | I8: II/2025 | J8: 2 | K8: Cargo Academico-Administrativo | L8: Inició comisión académico-admon el 01/06/2023 como Director del Programa de Física
A9: 6 | B9: Ingeniería Civil | C9: 18416179 | D9: POLANIA OBANDO LUIS FERNANDO | E9: 39199 | F9: Maestría | G9: Asociado | H9: 5 | I9: II/2022 | J9: 11 | K9: Cargo Academico-Administrativo | L9: Inició comisión académico-admon el 01/05/2023 como Rector, estaba en comisión académico-admon como Vicerrector de Extensión desde el 30/12/2015
A10: 7 | B10: Ingeniería Civil | C10: 7503647 | D10: SALAZAR SALAZAR ORLANDO | E10: 28185 | F10: Maestría | G10: Titular | H10: 5 | I10: II/2025 | J10: 9 | K10: Cargo Academico-Administrativo | L10: Inició comisión académico-admon el 02/05/2023 como Vicerrector Académico
